Workbook

Sheet candidates
A1: forecast_id | B1: fundraising_id | C1: first_name | D1: last_name | E1: name | F1: state | G1: party | H1: incumbent | I1: district_codes | J1: office_types | K1: overperf_2024 | L1: overperf_2022 | M1: overperf_2020 | N1: composite_strength
A2: MW-000001 | B2: H4NJ05184 | C2: Aamir | D2: Arif | E2: Aamir Arif | F2: NJ | G2: OTH | H2: 0 | I2: NJ-05 | J2: federal
A3: MW-000002 | B3: H2NY10191 | C3: Aamir | D3: Sultan | E3: Aamir Sultan | F3: NY | G3: REP | H3: 0 | I3: NY-10 | J3: federal
A4: MW-000003 | B4: H2CA30275 | C4: Aarika | D4: Rhodes | E4: Aarika Rhodes | F4: CA | G4: DEM | H4: 0 | I4: CA-32 | J4: federal
A5: MW-000004 | B5: H0ME01127 | C5: Aaron | D5: Amede | E5: Aaron Amede | F5: ME | G5: DEM | H5: 0 | I5: ME-01 | J5: federal
A6: MW-000005 | B6: S4TX00599 | C6: Aaron | D6: Arguijo | E6: Aaron Arguijo | F6: TX | G6: DEM | H6: 0 | I6: TX-S | J6: federal
A7: MW-000006 | B7: H6FL06241 | C7: Aaron | D7: Baker | E7: Aaron Baker | F7: FL | G7: REP | H7: 0 | I7: FL-06 | J7: federal
A8: MW-000007 | B8: H4PA02069 | C8: Aaron | D8: Bashir | E8: Aaron Bashir | F8: PA | G8: REP | H8: 0 | I8: PA-02 | J8: federal | L8: 15.413777 | M8: 3.5696491 | N8: 5.2616675
A9: MW-000008 | B9: H2FL04211 | C9: Aaron | D9: Bean | E9: Aaron Bean | F9: FL | G9: REP | H9: 1 | I9: FL-04 | J9: federal | M9: 0.56542732 | N9: -2.4345727
A10: MW-000009 | B10: H2IN03236 | C10: Aaron | D10: Calkins | E10: Aaron Calkins | F10: IN | G10: DEM | H10: 0 | I10: IN-03 | J10: federal
A11: MW-000010 | B11: H6NY05093 | C11: Aaron | D11: Cherry | E11: Aaron Cherry | F11: NY | G11: REP | H11: 0 | I11: NY-05 | J11: federal
A12: MW-000011 | B12: H4IN09148 | C12: Aaron | D12: Cole | E12: Aaron Cole | F12: IN | G12: DEM | H12: 0 | I12: IN-09 | J12: federal
A13: MW-000012 | B13: GOV-407 | C13: Aaron | D13: Coleman | E13: Aaron Coleman | F13: KS | G13: OTH | H13: 0 | I13: KS-GOV | J13: state
A14: MW-000013 | B14: H6WA05197 | C14: Aaron | D14: Croft | E14: Aaron Croft | F14: WA | G14: IND | H14: 0 | I14: WA-05 | J14: federal
A15: MW-000014 | B15: H4FL01213 | C15: Aaron | D15: Dimmock | E15: Aaron Dimmock | F15: FL | G15: REP | H15: 0 | I15: FL-01 | J15: federal
A16: MW-000015 | B16: H6MT01152 | C16: Aaron | D16: Flint | E16: Aaron Flint | F16: MT | G16: REP | H16: 0 | I16: MT-01 | J16: federal
A17: MW-000016 | B17: GOV-120 | C17: Aaron | D17: Ford | E17: Aaron Ford | F17: NV | G17: DEM | H17: 0 | I17: NV-GOV | J17: state
A18: MW-000017 | B18: S2WI00318 | C18: Aaron | D18: Frank | E18: Aaron Frank | F18: WI | G18: IND | H18: 0 | I18: WI-S | J18: federal
A19: MW-000018 | B19: H6NY23559 | C19: Aaron | D19: Gies | E19: Aaron Gies | F19: NY | G19: DEM | H19: 0 | I19: NY-23 | J19: federal
A20: MW-000019 | B20: H8OH16090 | C20: Aaron | D20: Godfrey | E20: Aaron Godfrey | F20: OH | G20: DEM | H20: 0 | I20: OH-16 | J20: federal
A21: MW-000020 | B21: GOV-145 | C21: Aaron | D21: Guckian | E21: Aaron Guckian | F21: RI | G21: REP | H21: 0 | I21: RI-GOV | J21: state
... A52: MW-000051 | B52: H0KS02170 | C52: Abbie | D52: Hodgson | E52: Abbie Hodgson | F52: KS | G52: DEM | H52: 0 | I52: KS-02 | J52: federal
A53: MW-000052 | B53: S0OK00370 | C53: Abby | D53: Broyles | E53: Abby Broyles | F53: OK | G53: DEM | H53: 0 | I53: OK-05; OK-S | J53: federal | K53: 5.801429 | N53: 5.801429
A54: MW-000053 | B54: S2IA00164 | C54: Abby | D54: Finkenauer | E54: Abby Finkenauer | F54: IA | G54: DEM | H54: 0 | I54: IA-S | J54: federal
A55: MW-000054 | B55: H0CA29115 | C55: Abdeli | D55: Sanchez | E55: Abdeli Sanchez | F55: CA | G55: DEM | H55: 0 | I55: CA-29 | J55: federal
A56: MW-000055 | B56: H6MN02289 | C56: Abdi | D56: Abdulle | E56: Abdi Abdulle | F56: MN | G56: DEM | H56: 0 | I56: MN-02 | J56: federal
A57: MW-000056 | B57: S6MI00418 | C57: Abdul | D57: El-sayed | E57: Abdul El-sayed | F57: MI | G57: DEM | H57: 0 | I57: MI-S | J57: federal
A58: MW-000057 | B58: S4CA00860 | C58: Abdul | D58: Satari | E58: Abdul Satari | F58: CA | G58: IND | H58: 0 | I58: CA-S | J58: federal
A59: MW-000058 | B59: H0CA19223 | C59: Abdullah | D59: Issaq | E59: Abdullah Issaq | F59: CA | G59: DEM | H59: 0 | I59: CA-19 | J59: federal
A60: MW-000059 | B60: H4CA12246 | C60: Abdur | D60: Sikder | E60: Abdur Sikder | F60: CA | G60: DEM | H60: 0 | I60: CA-12 | J60: federal
A61: MW-000060 | B61: H0NY08090 | C61: Abe | D61: Garcia | E61: Abe Garcia | F61: NY | G61: DEM | H61: 0 | I61: NY-08 | J61: federal
A62: MW-000061 | B62: H6CA41224 | C62: Abel | D62: Chavez | E62: Abel Chavez | F62: CA | G62: DEM | H62: 0 | I62: CA-48 | J62: federal
A63: MW-000062 | B63: H6WV01152 | C63: Abel | D63: Clendenen | E63: Abel Clendenen | F63: WV | G63: REP | H63: 0 | I63: WV-01 | J63: federal
A64: MW-000063 | B64: H2TX30145 | C64: Abel | D64: Mulugheta | E64: Abel Mulugheta | F64: TX | G64: DEM | H64: 0 | I64: TX-30 | J64: federal
A65: MW-000064 | B65: H4MN05139 | C65: Abena | D65: Mckenzie | E65: Abena Mckenzie | F65: MN | G65: DEM | H65: 0 | I65: MN-05 | J65: federal
... A69: MW-000068 | B69: H2CO18011 | C69: Abigail | D69: Fordham | E69: Abigail Fordham | F69: CO | G69: IND | H69: 0 | I69: CO-18 | J69: federal
A70: MW-000069 | B70: H8VA07094 | C70: Abigail | D70: Spanberger | E70: Abigail Spanberger | F70: VA | G70: DEM | H70: 0 | I70: VA-07 | J70: federal | K70: -1.2333486 | L70: 1.9359689 | N70: 0.74747483
A71: MW-000070 | B71: H6TX19222 | C71: Abraham | D71: Enriquez | E71: Abraham Enriquez | F71: TX | G71: REP | H71: 0 | I71: TX-19 | J71: federal
A72: MW-000071 | B72: H4AZ08108 | C72: Abraham | D72: Hamadeh | E72: Abraham Hamadeh | F72: AZ | G72: REP | H72: 1 | I72: AZ-08 | J72: federal | M72: 4.081228 | N72: 1.081228
A73: MW-000072 | B73: H0IL03091 | C73: Abraham | D73: Matthew | E73: Abraham Matthew | F73: IL | G73: DEM | H73: 0 | I73: IL-03 | J73: federal
...

Sheet races
A1: district_code | B1: state | C1: district | D1: race_type | E1: dem_forecast_id | F1: dem_name | G1: rep_forecast_id | H1: rep_name | I1: composite_dem_strength | J1: composite_rep_strength | K1: composite_strength | L1: incumbent_party
A2: AK-01 | B2: {=_xlfn.TEXTSPLIT(A2,"-")} | C2: 01 | D2: house | E2: MW-007236 | F2: Matthew Schultz | G2: MW-008001 | H2: Nicholas Begich | I2: =IF(VLOOKUP(E2,candidates!A:N, 14, 0)=0, "", VLOOKUP(E2,candidates!A:N, 14, 0)) | J2: =IF(VLOOKUP(G2,candidates!A:N, 14, 0)=0, "", VLOOKUP(G2,candidates!A:N, 14, 0)) | K2: =IFERROR(IF(L2="REP",(0.75*J2)+(0.25*I2),IF(L2="DEM",(0.75*I2)+(0.25*J2),AVERAGE(I2,J2)/2)), IFERROR((J2+0)/IF(L2="OPEN", 2, 1), IFERROR((I2+0)/IF(L2="OPEN", 2, 1)+IF(L2="REP", -3, IF(L2="DEM", 3, 0)), ""))) | L2: =IF(VLOOKUP(E2,candidates!A:H,8,0)=1, "DEM", IF(VLOOKUP(G2,candidates!A:H,8,0)=1, "REP", "OPEN"))
A3: AK-SEN | B3: {=_xlfn.TEXTSPLIT(A3,"-")} | C3: SEN | D3: senate | E3: MW-007102 | F3: Mary Peltola | G3: MW-002374 | H3: Dan Sullivan | I3: =IF(VLOOKUP(E3,candidates!A:N, 14, 0)=0, "", VLOOKUP(E3,candidates!A:N, 14, 0)) | J3: =IF(VLOOKUP(G3,candidates!A:N, 14, 0)=0, "", VLOOKUP(G3,candidates!A:N, 14, 0)) | K3: =IFERROR(IF(L3="REP",(0.75*J3)+(0.25*I3),IF(L3="DEM",(0.75*I3)+(0.25*J3),AVERAGE(I3,J3)/2)), IFERROR((J3+0)/IF(L3="OPEN", 2, 1), IFERROR((I3+0)/IF(L3="OPEN", 2, 1)+IF(L3="REP", -3, IF(L3="DEM", 3, 0)), ""))) | L3: =IF(VLOOKUP(E3,candidates!A:H,8,0)=1, "DEM", IF(VLOOKUP(G3,candidates!A:H,8,0)=1, "REP", "OPEN"))
A4: AL-01 | B4: {=_xlfn.TEXTSPLIT(A4,"-")} | C4: 01 | D4: house | E4: MW-002058 | F4: Clyde Jones | G4: MW-008753 | H4: Rhett Marques | I4: =IF(VLOOKUP(E4,candidates!A:N, 14, 0)=0, "", VLOOKUP(E4,candidates!A:N, 14, 0)) | J4: =IF(VLOOKUP(G4,candidates!A:N, 14, 0)=0, "", VLOOKUP(G4,candidates!A:N, 14, 0)) | K4: =IFERROR(IF(L4="REP",(0.75*J4)+(0.25*I4),IF(L4="DEM",(0.75*I4)+(0.25*J4),AVERAGE(I4,J4)/2)), IFERROR((J4+0)/IF(L4="OPEN", 2, 1), IFERROR((I4+0)/IF(L4="OPEN", 2, 1)+IF(L4="REP", -3, IF(L4="DEM", 3, 0)), ""))) | L4: =IF(VLOOKUP(E4,candidates!A:H,8,0)=1, "DEM", IF(VLOOKUP(G4,candidates!A:H,8,0)=1, "REP", "OPEN"))
A5: AL-02 | B5: {=_xlfn.TEXTSPLIT(A5,"-")} | C5: 02 | D5: house | E5: MW-009798 | F5: Shomari Figures | G5: MW-003942 | H5: Hampton Harris | I5: =IF(VLOOKUP(E5,candidates!A:N, 14, 0)=0, "", VLOOKUP(E5,candidates!A:N, 14, 0)) | J5: =IF(VLOOKUP(G5,candidates!A:N, 14, 0)=0, "", VLOOKUP(G5,candidates!A:N, 14, 0)) | K5: =IFERROR(IF(L5="REP",(0.75*J5)+(0.25*I5),IF(L5="DEM",(0.75*I5)+(0.25*J5),AVERAGE(I5,J5)/2)), IFERROR((J5+0)/IF(L5="OPEN", 2, 1), IFERROR((I5+0)/IF(L5="OPEN", 2, 1)+IF(L5="REP", -3, IF(L5="DEM", 3, 0)), ""))) | L5: =IF(VLOOKUP(E5,candidates!A:H,8,0)=1, "DEM", IF(VLOOKUP(G5,candidates!A:H,8,0)=1, "REP", "OPEN"))
A6: AL-03 | B6: {=_xlfn.TEXTSPLIT(A6,"-")} | C6: 03 | D6: house | E6: MW-010772 | F6: Victor Mcinnis | G6: MW-007627 | H6: Michael Rogers | I6: =IF(VLOOKUP(E6,candidates!A:N, 14, 0)=0, "", VLOOKUP(E6,candidates!A:N, 14, 0)) | J6: =IF(VLOOKUP(G6,candidates!A:N, 14, 0)=0, "", VLOOKUP(G6,candidates!A:N, 14, 0)) | K6: =IFERROR(IF(L6="REP",(0.75*J6)+(0.25*I6),IF(L6="DEM",(0.75*I6)+(0.25*J6),AVERAGE(I6,J6)/2)), IFERROR((J6+0)/IF(L6="OPEN", 2, 1), IFERROR((I6+0)/IF(L6="OPEN", 2, 1)+IF(L6="REP", -3, IF(L6="DEM", 3, 0)), ""))) | L6: =IF(VLOOKUP(E6,candidates!A:H,8,0)=1, "DEM", IF(VLOOKUP(G6,candidates!A:H,8,0)=1, "REP", "OPEN"))
A7: AL-04 | B7: {=_xlfn.TEXTSPLIT(A7,"-")} | C7: 04 | D7: house | E7: MW-000414 | F7: Amanda Pusczek | G7: MW-008913 | H7: Robert Aderholt | I7: =IF(VLOOKUP(E7,candidates!A:N, 14, 0)=0, "", VLOOKUP(E7,candidates!A:N, 14, 0)) | J7: =IF(VLOOKUP(G7,candidates!A:N, 14, 0)=0, "", VLOOKUP(G7,candidates!A:N, 14, 0)) | K7: =IFERROR(IF(L7="REP",(0.75*J7)+(0.25*I7),IF(L7="DEM",(0.75*I7)+(0.25*J7),AVERAGE(I7,J7)/2)), IFERROR((J7+0)/IF(L7="OPEN", 2, 1), IFERROR((I7+0)/IF(L7="OPEN", 2, 1)+IF(L7="REP", -3, IF(L7="DEM", 3, 0)), ""))) | L7: =IF(VLOOKUP(E7,candidates!A:H,8,0)=1, "DEM", IF(VLOOKUP(G7,candidates!A:H,8,0)=1, "REP", "OPEN"))
A8: AL-05 | B8: {=_xlfn.TEXTSPLIT(A8,"-")} | C8: 05 | D8: house | E8: MW-000569 | F8: Andrew Sneed | G8: MW-002228 | H8: Dale Strong | I8: =IF(VLOOKUP(E8,candidates!A:N, 14, 0)=0, "", VLOOKUP(E8,candidates!A:N, 14, 0)) | J8: =IF(VLOOKUP(G8,candidates!A:N, 14, 0)=0, "", VLOOKUP(G8,candidates!A:N, 14, 0)) | K8: =IFERROR(IF(L8="REP",(0.75*J8)+(0.25*I8),IF(L8="DEM",(0.75*I8)+(0.25*J8),AVERAGE(I8,J8)/2)), IFERROR((J8+0)/IF(L8="OPEN", 2, 1), IFERROR((I8+0)/IF(L8="OPEN", 2, 1)+IF(L8="REP", -3, IF(L8="DEM", 3, 0)), ""))) | L8: =IF(VLOOKUP(E8,candidates!A:H,8,0)=1, "DEM", IF(VLOOKUP(G8,candidates!A:H,8,0)=1, "REP", "OPEN"))
A9: AL-06 | B9: {=_xlfn.TEXTSPLIT(A9,"-")} | C9: 06 | D9: house | E9: MW-003177 | F9: Elizabeth Anderson | G9: MW-003632 | H9: Gary Palmer | I9: =IF(VLOOKUP(E9,candidates!A:N, 14, 0)=0, "", VLOOKUP(E9,candidates!A:N, 14, 0)) | J9: =IF(VLOOKUP(G9,candidates!A:N, 14, 0)=0, "", VLOOKUP(G9,candidates!A:N, 14, 0)) | K9: =IFERROR(IF(L9="REP",(0.75*J9)+(0.25*I9),IF(L9="DEM",(0.75*I9)+(0.25*J9),AVERAGE(I9,J9)/2)), IFERROR((J9+0)/IF(L9="OPEN", 2, 1), IFERROR((I9+0)/IF(L9="OPEN", 2, 1)+IF(L9="REP", -3, IF(L9="DEM", 3, 0)), ""))) | L9: =IF(VLOOKUP(E9,candidates!A:H,8,0)=1, "DEM", IF(VLOOKUP(G9,candidates!A:H,8,0)=1, "REP", "OPEN"))
A10: AL-07 | B10: {=_xlfn.TEXTSPLIT(A10,"-")} | C10: 07 | D10: house | E10: MW-010253 | F10: Terri Sewell | G10: MW-003679 | H10: Generic Republican | I10: =IF(VLOOKUP(E10,candidates!A:N, 14, 0)=0, "", VLOOKUP(E10,candidates!A:N, 14, 0)) | J10: =IF(VLOOKUP(G10,candidates!A:N, 14, 0)=0, "", VLOOKUP(G10,candidates!A:N, 14, 0)) | K10: =IFERROR(IF(L10="REP",(0.75*J10)+(0.25*I10),IF(L10="DEM",(0.75*I10)+(0.25*J10),AVERAGE(I10,J10)/2)), IFERROR((J10+0)/IF(L10="OPEN", 2, 1), IFERROR((I10+0)/IF(L10="OPEN", 2, 1)+IF(L10="REP", -3, IF(L10="DEM", 3, 0)), ""))) | L10: =IF(VLOOKUP(E10,candidates!A:H,8,0)=1, "DEM", IF(VLOOKUP(G10,candidates!A:H,8,0)=1, "REP", "OPEN"))
A11: AL-SEN | B11: {=_xlfn.TEXTSPLIT(A11,"-")} | C11: SEN | D11: senate | E11: MW-006346 | F11: Kyle Sweetser | G11: MW-003483 | H11: Felix Moore | I11: =IF(VLOOKUP(E11,candidates!A:N, 14, 0)=0, "", VLOOKUP(E11,candidates!A:N, 14, 0)) | J11: =IF(VLOOKUP(G11,candidates!A:N, 14, 0)=0, "", VLOOKUP(G11,candidates!A:N, 14, 0)) | K11: =IFERROR(IF(L11="REP",(0.75*J11)+(0.25*I11),IF(L11="DEM",(0.75*I11)+(0.25*J11),AVERAGE(I11,J11)/2)), IFERROR((J11+0)/IF(L11="OPEN", 2, 1), IFERROR((I11+0)/IF(L11="OPEN", 2, 1)+IF(L11="REP", -3, IF(L11="DEM", 3, 0)), ""))) | L11: =IF(VLOOKUP(E11,candidates!A:H,8,0)=1, "DEM", IF(VLOOKUP(G11,candidates!A:H,8,0)=1, "REP", "OPEN"))
A12: AR-01 | B12: {=_xlfn.TEXTSPLIT(A12,"-")} | C12: 01 | D12: house | E12: MW-010247 | F12: Terri Green | G12: MW-003280 | H12: Eric Crawford | I12: =IF(VLOOKUP(E12,candidates!A:N, 14, 0)=0, "", VLOOKUP(E12,candidates!A:N, 14, 0)) | J12: =IF(VLOOKUP(G12,candidates!A:N, 14, 0)=0, "", VLOOKUP(G12,candidates!A:N, 14, 0)) | K12: =IFERROR(IF(L12="REP",(0.75*J12)+(0.25*I12),IF(L12="DEM",(0.75*I12)+(0.25*J12),AVERAGE(I12,J12)/2)), IFERROR((J12+0)/IF(L12="OPEN", 2, 1), IFERROR((I12+0)/IF(L12="OPEN", 2, 1)+IF(L12="REP", -3, IF(L12="DEM", 3, 0)), ""))) | L12: =IF(VLOOKUP(E12,candidates!A:H,8,0)=1, "DEM", IF(VLOOKUP(G12,candidates!A:H,8,0)=1, "REP", "OPEN"))
A13: AR-02 | B13: {=_xlfn.TEXTSPLIT(A13,"-")} | C13: 02 | D13: house | E13: MW-001878 | F13: Chris Jones | G13: MW-004373 | H13: James Hill | I13: =IF(VLOOKUP(E13,candidates!A:N, 14, 0)=0, "", VLOOKUP(E13,candidates!A:N, 14, 0)) | J13: =IF(VLOOKUP(G13,candidates!A:N, 14, 0)=0, "", VLOOKUP(G13,candidates!A:N, 14, 0)) | K13: =IFERROR(IF(L13="REP",(0.75*J13)+(0.25*I13),IF(L13="DEM",(0.75*I13)+(0.25*J13),AVERAGE(I13,J13)/2)), IFERROR((J13+0)/IF(L13="OPEN", 2, 1), IFERROR((I13+0)/IF(L13="OPEN", 2, 1)+IF(L13="REP", -3, IF(L13="DEM", 3, 0)), ""))) | L13: =IF(VLOOKUP(E13,candidates!A:H,8,0)=1, "DEM", IF(VLOOKUP(G13,candidates!A:H,8,0)=1, "REP", "OPEN"))
... A510: WY-GOV | B510: {=_xlfn.TEXTSPLIT(A510,"-")} | C510: GOV | D510: governor | E510: MW-003580 | F510: Gabriel Green | G510: MW-007304 | H510: Megan Degenfelder | I510: =IF(VLOOKUP(E510,candidates!A:N, 14, 0)=0, "", VLOOKUP(E510,candidates!A:N, 14, 0)) | J510: =IF(VLOOKUP(G510,candidates!A:N, 14, 0)=0, "", VLOOKUP(G510,candidates!A:N, 14, 0)) | K510: =IFERROR(IF(L510="REP",(0.75*J510)+(0.25*I510),IF(L510="DEM",(0.75*I510)+(0.25*J510),AVERAGE(I510,J510)/2)), IFERROR((J510+0)/IF(L510="OPEN", 2, 1), IFERROR((I510+0)/IF(L510="OPEN", 2, 1)+IF(L510="REP", -3, IF(L510="DEM", 3, 0)), ""))) | L510: =IF(VLOOKUP(E510,candidates!A:H,8,0)=1, "DEM", IF(VLOOKUP(G510,candidates!A:H,8,0)=1, "REP", "OPEN"))
