Workbook
Name house: districts!$A$1:$K$436

Sheet districts
A1: State | B1: District | C1: District Code | D1: Trump '16 | E1: Clinton '16 | F1: Trump '20 | G1: Biden '20 | H1: Trump '24 | I1: Harris '24 | J1: Margin '16 | K1: Margin '20 | L1: Margin '24
A2: AK | B2: 1 | C2: AK-01 | D2: 163387 | E2: 116454 | F2: 189951 | G2: 153778 | H2: 184458 | I2: 140026 | J2: =(E2-D2)/(E2+D2)*100 -> -16.771309 | K2: =(G2-F2)/(G2+F2)*100 -> -10.523697 | L2: =(I2-H2)/(I2+H2)*100 -> -13.693125
A3: AL | B3: 1 | C3: AL-01 | D3: 219528 | E3: 64543 | F3: 242615 | G3: 79475 | H3: 257309 | I3: 73202 | J3: =(E3-D3)/(E3+D3)*100 -> -54.558543 | K3: =(G3-F3)/(G3+F3)*100 -> -50.650439 | L3: =(I3-H3)/(I3+H3)*100 -> -55.703744
A4: AL | B4: 2 | C4: AL-02 | D4: 132446 | E4: 162800 | F4: 136081 | G4: 173588 | H4: 131501 | I4: 155343 | J4: =(E4-D4)/(E4+D4)*100 -> 10.280918 | K4: =(G4-F4)/(G4+F4)*100 -> 12.111965 | L4: =(I4-H4)/(I4+H4)*100 -> 8.311835
A5: AL | B5: 3 | C5: AL-03 | D5: 200498 | E5: 79534 | F5: 225369 | G5: 93350 | H5: 230168 | I5: 82876 | J5: =(E5-D5)/(E5+D5)*100 -> -43.196492 | K5: =(G5-F5)/(G5+F5)*100 -> -41.421754 | L5: =(I5-H5)/(I5+H5)*100 -> -47.051533
A6: AL | B6: 4 | C6: AL-04 | D6: 236382 | E6: 51864 | F6: 262493 | G6: 60090 | H6: 258636 | I6: 49720 | J6: =(E6-D6)/(E6+D6)*100 -> -64.014071 | K6: =(G6-F6)/(G6+F6)*100 -> -62.744472 | L6: =(I6-H6)/(I6+H6)*100 -> -67.75156
A7: AL | B7: 5 | C7: AL-05 | D7: 189857 | E7: 92161 | F7: 216451 | G7: 122859 | H7: 233123 | I7: 124533 | J7: =(E7-D7)/(E7+D7)*100 -> -34.64176 | K7: =(G7-F7)/(G7+F7)*100 -> -27.583036 | L7: =(I7-H7)/(I7+H7)*100 -> -30.361576
A8: AL | B8: 6 | C8: AL-06 | D8: 225339 | E8: 80167 | F8: 242147 | G8: 107539 | H8: 240522 | I8: 104267 | J8: =(E8-D8)/(E8+D8)*100 -> -47.518543 | K8: =(G8-F8)/(G8+F8)*100 -> -38.493963 | L8: =(I8-H8)/(I8+H8)*100 -> -39.518372
A9: AL | B9: 7 | C9: AL-07 | D9: 114556 | E9: 198521 | F9: 115999 | G9: 212705 | H9: 111356 | I9: 182469 | J9: =(E9-D9)/(E9+D9)*100 -> 26.819281 | K9: =(G9-F9)/(G9+F9)*100 -> 29.42039 | L9: =(I9-H9)/(I9+H9)*100 -> 24.202501
A10: AR | B10: 1 | C10: AR-01 | D10: 178516 | E10: 82086 | F10: 197486 | G10: 79697 | H10: 196035 | I10: 72184 | J10: =(E10-D10)/(E10+D10)*100 -> -37.002786 | K10: =(G10-F10)/(G10+F10)*100 -> -42.49503 | L10: =(I10-H10)/(I10+H10)*100 -> -46.175327
A11: AR | B11: 2 | C11: AR-02 | D11: 166651 | E11: 120728 | F11: 183645 | G11: 140201 | H11: 180710 | I11: 131088 | J11: =(E11-D11)/(E11+D11)*100 -> -15.979943 | K11: =(G11-F11)/(G11+F11)*100 -> -13.415018 | L11: =(I11-H11)/(I11+H11)*100 -> -15.914791
A12: AR | B12: 3 | C12: AR-03 | D12: 156559 | E12: 82402 | F12: 180639 | G12: 110437 | H12: 189161 | I12: 112073 | J12: =(E12-D12)/(E12+D12)*100 -> -31.033097 | K12: =(G12-F12)/(G12+F12)*100 -> -24.1181 | L12: =(I12-H12)/(I12+H12)*100 -> -25.590737
A13: AR | B13: 4 | C13: AR-04 | D13: 182563 | E13: 93776 | F13: 197902 | G13: 91965 | H13: 193335 | I13: 81560 | J13: =(E13-D13)/(E13+D13)*100 -> -32.129739 | K13: =(G13-F13)/(G13+F13)*100 -> -36.546761 | L13: =(I13-H13)/(I13+H13)*100 -> -40.66098
... A436: WY | B436: 1 | C436: WY-01 | D436: 174419 | E436: 55973 | F436: 193559 | G436: 73491 | H436: 192633 | I436: 69527 | J436: =(E436-D436)/(E436+D436)*100 -> -51.410639 | K436: =(G436-F436)/(G436+F436)*100 -> -44.960869 | L436: =(I436-H436)/(I436+H436)*100 -> -46.958346

Sheet states
A1: State | B1: Trump '16 | C1: Clinton '16 | D1: Trump '20 | E1: Biden '20 | F1: Trump '24 | G1: Harris '24 | H1: Margin '16 | I1: Margin '20 | J1: Margin '24
A2: AK | B2: =SUMIF(districts!A:A,"AK",districts!D:D) -> 163387 | C2: =SUMIF(districts!A:A,"AK",districts!E:E) -> 116454 | D2: =SUMIF(districts!A:A,"AK",districts!F:F) -> 189951 | E2: =SUMIF(districts!A:A,"AK",districts!G:G) -> 153778 | F2: =SUMIF(districts!A:A,"AK",districts!H:H) -> 184458 | G2: =SUMIF(districts!A:A,"AK",districts!I:I) -> 140026 | H2: =(C2-B2)/(C2+B2)*100 -> -16.771309 | I2: =(E2-D2)/(E2+D2)*100 -> -10.523697 | J2: =(G2-F2)/(G2+F2)*100 -> -13.693125
A3: AL | B3: =SUMIF(districts!A:A,"AL",districts!D:D) -> 1318606 | C3: =SUMIF(districts!A:A,"AL",districts!E:E) -> 729590 | D3: =SUMIF(districts!A:A,"AL",districts!F:F) -> 1441155 | E3: =SUMIF(districts!A:A,"AL",districts!G:G) -> 849606 | F3: =SUMIF(districts!A:A,"AL",districts!H:H) -> 1462615 | G3: =SUMIF(districts!A:A,"AL",districts!I:I) -> 772410 | H3: =(C3-B3)/(C3+B3)*100 -> -28.757795 | I3: =(E3-D3)/(E3+D3)*100 -> -25.823253 | J3: =(G3-F3)/(G3+F3)*100 -> -30.88131
A4: AR | B4: =SUMIF(districts!A:A,"AR",districts!D:D) -> 684289 | C4: =SUMIF(districts!A:A,"AR",districts!E:E) -> 378992 | D4: =SUMIF(districts!A:A,"AR",districts!F:F) -> 759672 | E4: =SUMIF(districts!A:A,"AR",districts!G:G) -> 422300 | F4: =SUMIF(districts!A:A,"AR",districts!H:H) -> 759241 | G4: =SUMIF(districts!A:A,"AR",districts!I:I) -> 396905 | H4: =(C4-B4)/(C4+B4)*100 -> -28.71273 | I4: =(E4-D4)/(E4+D4)*100 -> -28.543147 | J4: =(G4-F4)/(G4+F4)*100 -> -31.339986
A5: AZ | B5: =SUMIF(districts!A:A,"AZ",districts!D:D) -> 1249676 | C5: =SUMIF(districts!A:A,"AZ",districts!E:E) -> 1160578 | D5: =SUMIF(districts!A:A,"AZ",districts!F:F) -> 1661284 | E5: =SUMIF(districts!A:A,"AZ",districts!G:G) -> 1671572 | F5: =SUMIF(districts!A:A,"AZ",districts!H:H) -> 1770242 | G5: =SUMIF(districts!A:A,"AZ",districts!I:I) -> 1582860 | H5: =(C5-B5)/(C5+B5)*100 -> -3.6966228 | I5: =(E5-D5)/(E5+D5)*100 -> 0.3086842 | J5: =(G5-F5)/(G5+F5)*100 -> -5.5883179
A6: CA | B6: =SUMIF(districts!A:A,"CA",districts!D:D) -> 4483301 | C6: =SUMIF(districts!A:A,"CA",districts!E:E) -> 8752066 | D6: =SUMIF(districts!A:A,"CA",districts!F:F) -> 6006428 | E6: =SUMIF(districts!A:A,"CA",districts!G:G) -> 11110493 | F6: =SUMIF(districts!A:A,"CA",districts!H:H) -> 6077541 | G6: =SUMIF(districts!A:A,"CA",districts!I:I) -> 9273042 | H6: =(C6-B6)/(C6+B6)*100 -> 32.252714 | I6: =(E6-D6)/(E6+D6)*100 -> 29.818827 | J6: =(G6-F6)/(G6+F6)*100 -> 20.816805
A7: CO | B7: =SUMIF(districts!A:A,"CO",districts!D:D) -> 1202349 | C7: =SUMIF(districts!A:A,"CO",districts!E:E) -> 1337987 | D7: =SUMIF(districts!A:A,"CO",districts!F:F) -> 1364637 | E7: =SUMIF(districts!A:A,"CO",districts!G:G) -> 1803839 | F7: =SUMIF(districts!A:A,"CO",districts!H:H) -> 1377441 | G7: =SUMIF(districts!A:A,"CO",districts!I:I) -> 1728161 | H7: =(C7-B7)/(C7+B7)*100 -> 5.3393724 | I7: =(E7-D7)/(E7+D7)*100 -> 13.861617 | J7: =(G7-F7)/(G7+F7)*100 -> 11.293141
A8: CT | B8: =SUMIF(districts!A:A,"CT",districts!D:D) -> 673215 | C8: =SUMIF(districts!A:A,"CT",districts!E:E) -> 897541 | D8: =SUMIF(districts!A:A,"CT",districts!F:F) -> 714790 | E8: =SUMIF(districts!A:A,"CT",districts!G:G) -> 1080696 | F8: =SUMIF(districts!A:A,"CT",districts!H:H) -> 736918 | G8: =SUMIF(districts!A:A,"CT",districts!I:I) -> 992053 | H8: =(C8-B8)/(C8+B8)*100 -> 14.281403 | I8: =(E8-D8)/(E8+D8)*100 -> 20.379218 | J8: =(G8-F8)/(G8+F8)*100 -> 14.756465
A9: DE | B9: =SUMIF(districts!A:A,"DE",districts!D:D) -> 185127 | C9: =SUMIF(districts!A:A,"DE",districts!E:E) -> 235603 | D9: =SUMIF(districts!A:A,"DE",districts!F:F) -> 200603 | E9: =SUMIF(districts!A:A,"DE",districts!G:G) -> 296268 | F9: =SUMIF(districts!A:A,"DE",districts!H:H) -> 214351 | G9: =SUMIF(districts!A:A,"DE",districts!I:I) -> 289758 | H9: =(C9-B9)/(C9+B9)*100 -> 11.997243 | I9: =(E9-D9)/(E9+D9)*100 -> 19.253488 | J9: =(G9-F9)/(G9+F9)*100 -> 14.958471
A10: FL | B10: =SUMIF(districts!A:A,"FL",districts!D:D) -> 4617216 | C10: =SUMIF(districts!A:A,"FL",districts!E:E) -> 4504070 | D10: =SUMIF(districts!A:A,"FL",districts!F:F) -> 5668377 | E10: =SUMIF(districts!A:A,"FL",districts!G:G) -> 5296464 | F10: =SUMIF(districts!A:A,"FL",districts!H:H) -> 6108350 | G10: =SUMIF(districts!A:A,"FL",districts!I:I) -> 4679230 | H10: =(C10-B10)/(C10+B10)*100 -> -1.240461 | I10: =(E10-D10)/(E10+D10)*100 -> -3.3918686 | J10: =(G10-F10)/(G10+F10)*100 -> -13.247828
A11: GA | B11: =SUMIF(districts!A:A,"GA",districts!D:D) -> 2087969 | C11: =SUMIF(districts!A:A,"GA",districts!E:E) -> 1876505 | D11: =SUMIF(districts!A:A,"GA",districts!F:F) -> 2461422 | E11: =SUMIF(districts!A:A,"GA",districts!G:G) -> 2473253 | F11: =SUMIF(districts!A:A,"GA",districts!H:H) -> 2663073 | G11: =SUMIF(districts!A:A,"GA",districts!I:I) -> 2547775 | H11: =(C11-B11)/(C11+B11)*100 -> -5.3339737 | I11: =(E11-D11)/(E11+D11)*100 -> 0.23975236 | J11: =(G11-F11)/(G11+F11)*100 -> -2.2126533
A12: HI | B12: =SUMIF(districts!A:A,"HI",districts!D:D) -> 128844 | C12: =SUMIF(districts!A:A,"HI",districts!E:E) -> 266891 | D12: =SUMIF(districts!A:A,"HI",districts!F:F) -> 196861 | E12: =SUMIF(districts!A:A,"HI",districts!G:G) -> 366128 | F12: =SUMIF(districts!A:A,"HI",districts!H:H) -> 193661 | G12: =SUMIF(districts!A:A,"HI",districts!I:I) -> 313044 | H12: =(C12-B12)/(C12+B12)*100 -> 34.883697 | I12: =(E12-D12)/(E12+D12)*100 -> 30.065774 | J12: =(G12-F12)/(G12+F12)*100 -> 23.560652
A13: IA | B13: =SUMIF(districts!A:A,"IA",districts!D:D) -> 800959 | C13: =SUMIF(districts!A:A,"IA",districts!E:E) -> 653645 | D13: =SUMIF(districts!A:A,"IA",districts!F:F) -> 897634 | E13: =SUMIF(districts!A:A,"IA",districts!G:G) -> 759044 | F13: =SUMIF(districts!A:A,"IA",districts!H:H) -> 927019 | G13: =SUMIF(districts!A:A,"IA",districts!I:I) -> 707278 | H13: =(C13-B13)/(C13+B13)*100 -> -10.12743 | I13: =(E13-D13)/(E13+D13)*100 -> -8.3655363 | J13: =(G13-F13)/(G13+F13)*100 -> -13.445598
A14: ID | B14: =SUMIF(districts!A:A,"ID",districts!D:D) -> 409050 | C14: =SUMIF(districts!A:A,"ID",districts!E:E) -> 189747 | D14: =SUMIF(districts!A:A,"ID",districts!F:F) -> 554115 | E14: =SUMIF(districts!A:A,"ID",districts!G:G) -> 287006 | F14: =SUMIF(districts!A:A,"ID",districts!H:H) -> 605246 | G14: =SUMIF(districts!A:A,"ID",districts!I:I) -> 274972 | H14: =(C14-B14)/(C14+B14)*100 -> -36.623931 | I14: =(E14-D14)/(E14+D14)*100 -> -31.756311 | J14: =(G14-F14)/(G14+F14)*100 -> -37.521841
A15: IL | B15: =SUMIF(districts!A:A,"IL",districts!D:D) -> 2145898 | C15: =SUMIF(districts!A:A,"IL",districts!E:E) -> 3090546 | D15: =SUMIF(districts!A:A,"IL",districts!F:F) -> 2446742 | E15: =SUMIF(districts!A:A,"IL",districts!G:G) -> 3471737 | F15: =SUMIF(districts!A:A,"IL",districts!H:H) -> 2449080 | G15: =SUMIF(districts!A:A,"IL",districts!I:I) -> 3062864 | H15: =(C15-B15)/(C15+B15)*100 -> 18.039876 | I15: =(E15-D15)/(E15+D15)*100 -> 17.318554 | J15: =(G15-F15)/(G15+F15)*100 -> 11.135527
A16: IN | B16: =SUMIF(districts!A:A,"IN",districts!D:D) -> 1556335 | C16: =SUMIF(districts!A:A,"IN",districts!E:E) -> 1031777 | D16: =SUMIF(districts!A:A,"IN",districts!F:F) -> 1728953 | E16: =SUMIF(districts!A:A,"IN",districts!G:G) -> 1241537 | F16: =SUMIF(districts!A:A,"IN",districts!H:H) -> 1720835 | G16: =SUMIF(districts!A:A,"IN",districts!I:I) -> 1164352 | H16: =(C16-B16)/(C16+B16)*100 -> -20.267979 | I16: =(E16-D16)/(E16+D16)*100 -> -16.408606 | J16: =(G16-F16)/(G16+F16)*100 -> -19.287589
A17: KS | B17: =SUMIF(districts!A:A,"KS",districts!D:D) -> 669797 | C17: =SUMIF(districts!A:A,"KS",districts!E:E) -> 422712 | D17: =SUMIF(districts!A:A,"KS",districts!F:F) -> 770736 | E17: =SUMIF(districts!A:A,"KS",districts!G:G) -> 567053 | F17: =SUMIF(districts!A:A,"KS",districts!H:H) -> 758802 | G17: =SUMIF(districts!A:A,"KS",districts!I:I) -> 544853 | H17: =(C17-B17)/(C17+B17)*100 -> -22.61629 | I17: =(E17-D17)/(E17+D17)*100 -> -15.225346 | J17: =(G17-F17)/(G17+F17)*100 -> -16.411474
A18: KY | B18: =SUMIF(districts!A:A,"KY",districts!D:D) -> 1202625 | C18: =SUMIF(districts!A:A,"KY",districts!E:E) -> 627663 | D18: =SUMIF(districts!A:A,"KY",districts!F:F) -> 1326283 | E18: =SUMIF(districts!A:A,"KY",districts!G:G) -> 771597 | F18: =SUMIF(districts!A:A,"KY",districts!H:H) -> 1337494 | G18: =SUMIF(districts!A:A,"KY",districts!I:I) -> 704043 | H18: =(C18-B18)/(C18+B18)*100 -> -31.413745 | I18: =(E18-D18)/(E18+D18)*100 -> -26.440311 | J18: =(G18-F18)/(G18+F18)*100 -> -31.028142
A19: LA | B19: =SUMIF(districts!A:A,"LA",districts!D:D) -> 1177552 | C19: =SUMIF(districts!A:A,"LA",districts!E:E) -> 779211 | D19: =SUMIF(districts!A:A,"LA",districts!F:F) -> 1254849 | E19: =SUMIF(districts!A:A,"LA",districts!G:G) -> 855090 | F19: =SUMIF(districts!A:A,"LA",districts!H:H) -> 1208352 | G19: =SUMIF(districts!A:A,"LA",districts!I:I) -> 766981 | H19: =(C19-B19)/(C19+B19)*100 -> -20.357141 | I19: =(E19-D19)/(E19+D19)*100 -> -18.946472 | J19: =(G19-F19)/(G19+F19)*100 -> -22.344131
A20: MA | B20: =SUMIF(districts!A:A,"MA",districts!D:D) -> 1090757 | C20: =SUMIF(districts!A:A,"MA",districts!E:E) -> 1995046 | D20: =SUMIF(districts!A:A,"MA",districts!F:F) -> 1167119 | E20: =SUMIF(districts!A:A,"MA",districts!G:G) -> 2382039 | F20: =SUMIF(districts!A:A,"MA",districts!H:H) -> 1251303 | G20: =SUMIF(districts!A:A,"MA",districts!I:I) -> 2126518 | H20: =(C20-B20)/(C20+B20)*100 -> 29.30482 | I20: =(E20-D20)/(E20+D20)*100 -> 34.231218 | J20: =(G20-F20)/(G20+F20)*100 -> 25.910639
A21: MD | B21: =SUMIF(districts!A:A,"MD",districts!D:D) -> 942521 | C21: =SUMIF(districts!A:A,"MD",districts!E:E) -> 1677891 | D21: =SUMIF(districts!A:A,"MD",districts!F:F) -> 976141 | E21: =SUMIF(districts!A:A,"MD",districts!G:G) -> 1984872 | F21: =SUMIF(districts!A:A,"MD",districts!H:H) -> 1035550 | G21: =SUMIF(districts!A:A,"MD",districts!I:I) -> 1902577 | H21: =(C21-B21)/(C21+B21)*100 -> 28.063144 | I21: =(E21-D21)/(E21+D21)*100 -> 34.067091 | J21: =(G21-F21)/(G21+F21)*100 -> 29.509514
A22: ME | B22: =SUMIF(districts!A:A,"ME",districts!D:D) -> 334786 | C22: =SUMIF(districts!A:A,"ME",districts!E:E) -> 354656 | D22: =SUMIF(districts!A:A,"ME",districts!F:F) -> 360763 | E22: =SUMIF(districts!A:A,"ME",districts!G:G) -> 435067 | F22: =SUMIF(districts!A:A,"ME",districts!H:H) -> 377977 | G22: =SUMIF(districts!A:A,"ME",districts!I:I) -> 435652 | H22: =(C22-B22)/(C22+B22)*100 -> 2.8820408 | I22: =(E22-D22)/(E22+D22)*100 -> 9.3366674 | J22: =(G22-F22)/(G22+F22)*100 -> 7.0886116
A23: MI | B23: =SUMIF(districts!A:A,"MI",districts!D:D) -> 2277860 | C23: =SUMIF(districts!A:A,"MI",districts!E:E) -> 2267491 | D23: =SUMIF(districts!A:A,"MI",districts!F:F) -> 2649832 | E23: =SUMIF(districts!A:A,"MI",districts!G:G) -> 2803955 | F23: =SUMIF(districts!A:A,"MI",districts!H:H) -> 2813835 | G23: =SUMIF(districts!A:A,"MI",districts!I:I) -> 2735334 | H23: =(C23-B23)/(C23+B23)*100 -> -0.2281232 | I23: =(E23-D23)/(E23+D23)*100 -> 2.8259813 | J23: =(G23-F23)/(G23+F23)*100 -> -1.4146442
A24: MN | B24: =SUMIF(districts!A:A,"MN",districts!D:D) -> 1320982 | C24: =SUMIF(districts!A:A,"MN",districts!E:E) -> 1363708 | D24: =SUMIF(districts!A:A,"MN",districts!F:F) -> 1484030 | E24: =SUMIF(districts!A:A,"MN",districts!G:G) -> 1717051 | F24: =SUMIF(districts!A:A,"MN",districts!H:H) -> 1519032 | G24: =SUMIF(districts!A:A,"MN",districts!I:I) -> 1656979 | H24: =(C24-B24)/(C24+B24)*100 -> 1.5914687 | I24: =(E24-D24)/(E24+D24)*100 -> 7.2794472 | J24: =(G24-F24)/(G24+F24)*100 -> 4.3434044
A25: MO | B25: =SUMIF(districts!A:A,"MO",districts!D:D) -> 1594462 | C25: =SUMIF(districts!A:A,"MO",districts!E:E) -> 1070919 | D25: =SUMIF(districts!A:A,"MO",districts!F:F) -> 1718717 | E25: =SUMIF(districts!A:A,"MO",districts!G:G) -> 1252968 | F25: =SUMIF(districts!A:A,"MO",districts!H:H) -> 1751986 | G25: =SUMIF(districts!A:A,"MO",districts!I:I) -> 1200599 | H25: =(C25-B25)/(C25+B25)*100 -> -19.642333 | I25: =(E25-D25)/(E25+D25)*100 -> -15.672893 | J25: =(G25-F25)/(G25+F25)*100 -> -18.674721
A26: MS | B26: =SUMIF(districts!A:A,"MS",districts!D:D) -> 700688 | C26: =SUMIF(districts!A:A,"MS",districts!E:E) -> 485107 | D26: =SUMIF(districts!A:A,"MS",districts!F:F) -> 756747 | E26: =SUMIF(districts!A:A,"MS",districts!G:G) -> 539373 | F26: =SUMIF(districts!A:A,"MS",districts!H:H) -> 747744 | G26: =SUMIF(districts!A:A,"MS",districts!I:I) -> 466667 | H26: =(C26-B26)/(C26+B26)*100 -> -18.180293 | I26: =(E26-D26)/(E26+D26)*100 -> -16.771132 | J26: =(G26-F26)/(G26+F26)*100 -> -23.14513
A27: MT | B27: =SUMIF(districts!A:A,"MT",districts!D:D) -> 278872 | C27: =SUMIF(districts!A:A,"MT",districts!E:E) -> 176795 | D27: =SUMIF(districts!A:A,"MT",districts!F:F) -> 343292 | E27: =SUMIF(districts!A:A,"MT",districts!G:G) -> 244041 | F27: =SUMIF(districts!A:A,"MT",districts!H:H) -> 352079 | G27: =SUMIF(districts!A:A,"MT",districts!I:I) -> 231906 | H27: =(C27-B27)/(C27+B27)*100 -> -22.401666 | I27: =(E27-D27)/(E27+D27)*100 -> -16.898591 | J27: =(G27-F27)/(G27+F27)*100 -> -20.578097
A28: NC | B28: =SUMIF(districts!A:A,"NC",districts!D:D) -> 2362631 | C28: =SUMIF(districts!A:A,"NC",districts!E:E) -> 2189316 | D28: =SUMIF(districts!A:A,"NC",districts!F:F) -> 2758775 | E28: =SUMIF(districts!A:A,"NC",districts!G:G) -> 2684292 | F28: =SUMIF(districts!A:A,"NC",districts!H:H) -> 2896941 | G28: =SUMIF(districts!A:A,"NC",districts!I:I) -> 2713609 | H28: =(C28-B28)/(C28+B28)*100 -> -3.8074916 | I28: =(E28-D28)/(E28+D28)*100 -> -1.3684013 | J28: =(G28-F28)/(G28+F28)*100 -> -3.2676297
A29: ND | B29: =SUMIF(districts!A:A,"ND",districts!D:D) -> 216794 | C29: =SUMIF(districts!A:A,"ND",districts!E:E) -> 93758 | D29: =SUMIF(districts!A:A,"ND",districts!F:F) -> 235595 | E29: =SUMIF(districts!A:A,"ND",districts!G:G) -> 114902 | F29: =SUMIF(districts!A:A,"ND",districts!H:H) -> 246505 | G29: =SUMIF(districts!A:A,"ND",districts!I:I) -> 112327 | H29: =(C29-B29)/(C29+B29)*100 -> -39.618486 | I29: =(E29-D29)/(E29+D29)*100 -> -34.434817 | J29: =(G29-F29)/(G29+F29)*100 -> -37.392986
A30: NE | B30: =SUMIF(districts!A:A,"NE",districts!D:D) -> 495938 | C30: =SUMIF(districts!A:A,"NE",districts!E:E) -> 284466 | D30: =SUMIF(districts!A:A,"NE",districts!F:F) -> 556850 | E30: =SUMIF(districts!A:A,"NE",districts!G:G) -> 374543 | F30: =SUMIF(districts!A:A,"NE",districts!H:H) -> 564816 | G30: =SUMIF(districts!A:A,"NE",districts!I:I) -> 369995 | H30: =(C30-B30)/(C30+B30)*100 -> -27.09776 | I30: =(E30-D30)/(E30+D30)*100 -> -19.573585 | J30: =(G30-F30)/(G30+F30)*100 -> -20.840683
A31: NH | B31: =SUMIF(districts!A:A,"NH",districts!D:D) -> 345791 | C31: =SUMIF(districts!A:A,"NH",districts!E:E) -> 348522 | D31: =SUMIF(districts!A:A,"NH",districts!F:F) -> 365659 | E31: =SUMIF(districts!A:A,"NH",districts!G:G) -> 424930 | F31: =SUMIF(districts!A:A,"NH",districts!H:H) -> 395523 | G31: =SUMIF(districts!A:A,"NH",districts!I:I) -> 418488 | H31: =(C31-B31)/(C31+B31)*100 -> 0.39333845 | I31: =(E31-D31)/(E31+D31)*100 -> 7.4970686 | J31: =(G31-F31)/(G31+F31)*100 -> 2.8212149
A32: NJ | B32: =SUMIF(districts!A:A,"NJ",districts!D:D) -> 1601929 | C32: =SUMIF(districts!A:A,"NJ",districts!E:E) -> 2148276 | D32: =SUMIF(districts!A:A,"NJ",districts!F:F) -> 1883272 | E32: =SUMIF(districts!A:A,"NJ",districts!G:G) -> 2608333 | F32: =SUMIF(districts!A:A,"NJ",districts!H:H) -> 1968216 | G32: =SUMIF(districts!A:A,"NJ",districts!I:I) -> 2220712 | H32: =(C32-B32)/(C32+B32)*100 -> 14.568457 | I32: =(E32-D32)/(E32+D32)*100 -> 16.142582 | J32: =(G32-F32)/(G32+F32)*100 -> 6.0276997
A33: NM | B33: =SUMIF(districts!A:A,"NM",districts!D:D) -> 319103 | C33: =SUMIF(districts!A:A,"NM",districts!E:E) -> 384548 | D33: =SUMIF(districts!A:A,"NM",districts!F:F) -> 401732 | E33: =SUMIF(districts!A:A,"NM",districts!G:G) -> 501056 | F33: =SUMIF(districts!A:A,"NM",districts!H:H) -> 422180 | G33: =SUMIF(districts!A:A,"NM",districts!I:I) -> 476068 | H33: =(C33-B33)/(C33+B33)*100 -> 9.3007755 | I33: =(E33-D33)/(E33+D33)*100 -> 11.001919 | J33: =(G33-F33)/(G33+F33)*100 -> 5.9992341
A34: NV | B34: =SUMIF(districts!A:A,"NV",districts!D:D) -> 511953 | C34: =SUMIF(districts!A:A,"NV",districts!E:E) -> 539014 | D34: =SUMIF(districts!A:A,"NV",districts!F:F) -> 669758 | E34: =SUMIF(districts!A:A,"NV",districts!G:G) -> 703174 | F34: =SUMIF(districts!A:A,"NV",districts!H:H) -> 751205 | G34: =SUMIF(districts!A:A,"NV",districts!I:I) -> 705197 | H34: =(C34-B34)/(C34+B34)*100 -> 2.5748668 | I34: =(E34-D34)/(E34+D34)*100 -> 2.4339152 | J34: =(G34-F34)/(G34+F34)*100 -> -3.1590179
A35: NY | B35: =SUMIF(districts!A:A,"NY",districts!D:D) -> 2819552 | C35: =SUMIF(districts!A:A,"NY",districts!E:E) -> 4556131 | D35: =SUMIF(districts!A:A,"NY",districts!F:F) -> 3251997 | E35: =SUMIF(districts!A:A,"NY",districts!G:G) -> 5244886 | F35: =SUMIF(districts!A:A,"NY",districts!H:H) -> 3579176 | G35: =SUMIF(districts!A:A,"NY",districts!I:I) -> 4619189 | H35: =(C35-B35)/(C35+B35)*100 -> 23.544653 | I35: =(E35-D35)/(E35+D35)*100 -> 23.454354 | J35: =(G35-F35)/(G35+F35)*100 -> 12.685615
A36: OH | B36: =SUMIF(districts!A:A,"OH",districts!D:D) -> 2841005 | C36: =SUMIF(districts!A:A,"OH",districts!E:E) -> 2394164 | D36: =SUMIF(districts!A:A,"OH",districts!F:F) -> 3154834 | E36: =SUMIF(districts!A:A,"OH",districts!G:G) -> 2679165 | F36: =SUMIF(districts!A:A,"OH",districts!H:H) -> 3180116 | G36: =SUMIF(districts!A:A,"OH",districts!I:I) -> 2533699 | H36: =(C36-B36)/(C36+B36)*100 -> -8.5353692 | I36: =(E36-D36)/(E36+D36)*100 -> -8.1533953 | J36: =(G36-F36)/(G36+F36)*100 -> -11.313229
A37: OK | B37: =SUMIF(districts!A:A,"OK",districts!D:D) -> 949126 | C37: =SUMIF(districts!A:A,"OK",districts!E:E) -> 420229 | D37: =SUMIF(districts!A:A,"OK",districts!F:F) -> 1020270 | E37: =SUMIF(districts!A:A,"OK",districts!G:G) -> 503792 | F37: =SUMIF(districts!A:A,"OK",districts!H:H) -> 1036214 | G37: =SUMIF(districts!A:A,"OK",districts!I:I) -> 499599 | H37: =(C37-B37)/(C37+B37)*100 -> -38.623805 | I37: =(E37-D37)/(E37+D37)*100 -> -33.888254 | J37: =(G37-F37)/(G37+F37)*100 -> -34.940126
A38: OR | B38: =SUMIF(districts!A:A,"OR",districts!D:D) -> 782318 | C38: =SUMIF(districts!A:A,"OR",districts!E:E) -> 1002075 | D38: =SUMIF(districts!A:A,"OR",districts!F:F) -> 958347 | E38: =SUMIF(districts!A:A,"OR",districts!G:G) -> 1340336 | F38: =SUMIF(districts!A:A,"OR",districts!H:H) -> 919585 | G38: =SUMIF(districts!A:A,"OR",districts!I:I) -> 1241387 | H38: =(C38-B38)/(C38+B38)*100 -> 12.315504 | I38: =(E38-D38)/(E38+D38)*100 -> 16.617733 | J38: =(G38-F38)/(G38+F38)*100 -> 14.89154
A39: PA | B39: =SUMIF(districts!A:A,"PA",districts!D:D) -> 2970832 | C39: =SUMIF(districts!A:A,"PA",districts!E:E) -> 2926339 | D39: =SUMIF(districts!A:A,"PA",districts!F:F) -> 3378037 | E39: =SUMIF(districts!A:A,"PA",districts!G:G) -> 3460347 | F39: =SUMIF(districts!A:A,"PA",districts!H:H) -> 3543308 | G39: =SUMIF(districts!A:A,"PA",districts!I:I) -> 3423042 | H39: =(C39-B39)/(C39+B39)*100 -> -0.75448041 | I39: =(E39-D39)/(E39+D39)*100 -> 1.2036469 | J39: =(G39-F39)/(G39+F39)*100 -> -1.7263847
A40: RI | B40: =SUMIF(districts!A:A,"RI",districts!D:D) -> 180515 | C40: =SUMIF(districts!A:A,"RI",districts!E:E) -> 252515 | D40: =SUMIF(districts!A:A,"RI",districts!F:F) -> 199897 | E40: =SUMIF(districts!A:A,"RI",districts!G:G) -> 307507 | F40: =SUMIF(districts!A:A,"RI",districts!H:H) -> 214406 | G40: =SUMIF(districts!A:A,"RI",districts!I:I) -> 285156 | H40: =(C40-B40)/(C40+B40)*100 -> 16.627024 | I40: =(E40-D40)/(E40+D40)*100 -> 21.207953 | J40: =(G40-F40)/(G40+F40)*100 -> 14.162406
...
